INFO 2023-04-24 01:12:03,179 Watching for file changes with StatReloader
INFO 2023-04-24 01:12:22,618 "GET / HTTP/1.1" 302 0
INFO 2023-04-24 01:12:23,073 "GET /accounts/login/?next=/ HTTP/1.1" 200 4827
INFO 2023-04-24 01:12:23,315 "GET /static/plugins/fontawesome-free/css/all.min.css HTTP/1.1" 200 367
INFO 2023-04-24 01:12:23,457 "GET /static/plugins/toastr/toastr.min.css HTTP/1.1" 200 367
INFO 2023-04-24 01:12:23,505 "GET /static/plugins/overlayScrollbars/css/OverlayScrollbars.min.css HTTP/1.1" 200 367
INFO 2023-04-24 01:12:23,508 "GET /static/dist/css/adminlte.min.css HTTP/1.1" 200 367
INFO 2023-04-24 01:12:23,512 "GET /static/dist/css/login-page.css HTTP/1.1" 200 367
INFO 2023-04-24 01:12:23,523 "GET /static/plugins/jquery/jquery.min.js HTTP/1.1" 200 367
INFO 2023-04-24 01:12:23,744 "GET /static/dist/js/jquery.formset.js HTTP/1.1" 200 367
INFO 2023-04-24 01:12:23,884 "GET /static/plugins/bootstrap/js/bootstrap.bundle.min.js HTTP/1.1" 200 367
INFO 2023-04-24 01:12:23,924 "GET /static/plugins/toastr/toastr.min.js HTTP/1.1" 200 367
INFO 2023-04-24 01:12:23,947 "GET /static/plugins/overlayScrollbars/js/jquery.overlayScrollbars.min.js HTTP/1.1" 200 367
INFO 2023-04-24 01:12:23,950 "GET /static/dist/js/adminlte.js HTTP/1.1" 200 367
INFO 2023-04-24 01:12:23,968 "GET /static/dist/js/demo.js HTTP/1.1" 200 367
INFO 2023-04-24 01:12:24,180 "GET /static/dist/img/login.png HTTP/1.1" 200 367
INFO 2023-04-24 01:12:24,621 "GET /favicon.ico HTTP/1.1" 200 367
WARNING 2023-04-24 02:33:34,049 Not Found: /robots.txt
WARNING 2023-04-24 07:04:05,662 Not Found: /wp-includes/wlwmanifest.xml
WARNING 2023-04-24 07:04:05,858 Not Found: /xmlrpc.php
WARNING 2023-04-24 07:04:06,247 Not Found: /blog/wp-includes/wlwmanifest.xml
WARNING 2023-04-24 07:04:06,444 Not Found: /web/wp-includes/wlwmanifest.xml
WARNING 2023-04-24 07:04:06,636 Not Found: /wordpress/wp-includes/wlwmanifest.xml
WARNING 2023-04-24 07:04:06,829 Not Found: /website/wp-includes/wlwmanifest.xml
WARNING 2023-04-24 07:04:07,026 Not Found: /wp/wp-includes/wlwmanifest.xml
WARNING 2023-04-24 07:04:07,216 Not Found: /news/wp-includes/wlwmanifest.xml
WARNING 2023-04-24 07:04:07,403 Not Found: /2020/wp-includes/wlwmanifest.xml
WARNING 2023-04-24 07:04:07,601 Not Found: /2019/wp-includes/wlwmanifest.xml
WARNING 2023-04-24 07:04:07,796 Not Found: /shop/wp-includes/wlwmanifest.xml
WARNING 2023-04-24 07:04:07,985 Not Found: /wp1/wp-includes/wlwmanifest.xml
WARNING 2023-04-24 07:04:08,178 Not Found: /test/wp-includes/wlwmanifest.xml
WARNING 2023-04-24 07:04:08,368 Not Found: /wp2/wp-includes/wlwmanifest.xml
WARNING 2023-04-24 07:04:08,559 Not Found: /site/wp-includes/wlwmanifest.xml
WARNING 2023-04-24 07:04:08,748 Not Found: /cms/wp-includes/wlwmanifest.xml
WARNING 2023-04-24 07:04:08,937 Not Found: /sito/wp-includes/wlwmanifest.xml
WARNING 2023-04-24 10:43:05,588 Not Found: /wp-login.php
WARNING 2023-04-24 10:53:36,233 Not Found: /robots.txt
WARNING 2023-04-24 10:53:36,498 Not Found: /ads.txt
WARNING 2023-04-24 12:41:06,155 Not Found: /wp-includes/wlwmanifest.xml
WARNING 2023-04-24 12:41:06,409 Not Found: /xmlrpc.php
WARNING 2023-04-24 12:41:06,800 Not Found: /blog/wp-includes/wlwmanifest.xml
WARNING 2023-04-24 12:41:06,999 Not Found: /web/wp-includes/wlwmanifest.xml
WARNING 2023-04-24 12:41:07,222 Not Found: /wordpress/wp-includes/wlwmanifest.xml
WARNING 2023-04-24 12:41:07,441 Not Found: /website/wp-includes/wlwmanifest.xml
WARNING 2023-04-24 12:41:07,638 Not Found: /wp/wp-includes/wlwmanifest.xml
WARNING 2023-04-24 12:41:07,839 Not Found: /news/wp-includes/wlwmanifest.xml
WARNING 2023-04-24 12:41:08,038 Not Found: /2018/wp-includes/wlwmanifest.xml
WARNING 2023-04-24 12:41:08,236 Not Found: /2019/wp-includes/wlwmanifest.xml
WARNING 2023-04-24 12:41:08,434 Not Found: /shop/wp-includes/wlwmanifest.xml
WARNING 2023-04-24 12:41:08,632 Not Found: /wp1/wp-includes/wlwmanifest.xml
WARNING 2023-04-24 12:41:08,831 Not Found: /test/wp-includes/wlwmanifest.xml
WARNING 2023-04-24 12:41:09,028 Not Found: /media/wp-includes/wlwmanifest.xml
WARNING 2023-04-24 12:41:09,225 Not Found: /wp2/wp-includes/wlwmanifest.xml
WARNING 2023-04-24 12:41:09,422 Not Found: /site/wp-includes/wlwmanifest.xml
WARNING 2023-04-24 12:41:09,621 Not Found: /cms/wp-includes/wlwmanifest.xml
WARNING 2023-04-24 12:41:09,819 Not Found: /sito/wp-includes/wlwmanifest.xml
WARNING 2023-04-24 18:24:25,978 Not Found: /wp-includes/wlwmanifest.xml
WARNING 2023-04-24 18:24:26,171 Not Found: /xmlrpc.php
WARNING 2023-04-24 18:24:26,560 Not Found: /blog/wp-includes/wlwmanifest.xml
WARNING 2023-04-24 18:24:26,756 Not Found: /web/wp-includes/wlwmanifest.xml
WARNING 2023-04-24 18:24:26,946 Not Found: /wordpress/wp-includes/wlwmanifest.xml
WARNING 2023-04-24 18:24:27,135 Not Found: /website/wp-includes/wlwmanifest.xml
WARNING 2023-04-24 18:24:27,328 Not Found: /wp/wp-includes/wlwmanifest.xml
WARNING 2023-04-24 18:24:27,515 Not Found: /news/wp-includes/wlwmanifest.xml
WARNING 2023-04-24 18:24:27,702 Not Found: /2020/wp-includes/wlwmanifest.xml
WARNING 2023-04-24 18:24:27,897 Not Found: /2019/wp-includes/wlwmanifest.xml
WARNING 2023-04-24 18:24:28,084 Not Found: /shop/wp-includes/wlwmanifest.xml
WARNING 2023-04-24 18:24:28,271 Not Found: /wp1/wp-includes/wlwmanifest.xml
WARNING 2023-04-24 18:24:28,474 Not Found: /test/wp-includes/wlwmanifest.xml
WARNING 2023-04-24 18:24:28,685 Not Found: /wp2/wp-includes/wlwmanifest.xml
WARNING 2023-04-24 18:24:28,876 Not Found: /site/wp-includes/wlwmanifest.xml
WARNING 2023-04-24 18:24:29,063 Not Found: /cms/wp-includes/wlwmanifest.xml
WARNING 2023-04-24 18:24:29,250 Not Found: /sito/wp-includes/wlwmanifest.xml
INFO 2023-04-24 22:04:11,494 Watching for file changes with StatReloader
INFO 2023-04-24 22:04:22,859 code 400, message Bad request version ('\x00\x02\x01\x00\x00')
ERROR 2023-04-24 22:04:22,860 You're accessing the development server over HTTPS, but it only supports HTTP.
INFO 2023-04-24 22:04:23,265 code 400, message Bad request syntax ("\x16\x03\x01\x02\x00\x01\x00\x01ü\x03\x03ú^~ø'Ï")
ERROR 2023-04-24 22:04:23,265 You're accessing the development server over HTTPS, but it only supports HTTP.
INFO 2023-04-24 22:04:29,781 code 400, message Bad request version ('\x02h2\x08http/1.1\x00')
ERROR 2023-04-24 22:04:29,781 You're accessing the development server over HTTPS, but it only supports HTTP.
INFO 2023-04-24 22:04:30,215 code 400, message Bad request version ('ÚÚ\x13\x01\x13\x02\x13\x03À+À/À,À0Ì©Ì¨À\x13À\x14\x00\x9c\x00\x9d\x00/\x005\x01\x00\x01\x93')
ERROR 2023-04-24 22:04:30,215 You're accessing the development server over HTTPS, but it only supports HTTP.
INFO 2023-04-24 22:04:33,617 code 400, message Bad request version ('[\xad(*\x1aÕP\x98ÿøÇyêþåðÒ±î\x05~5Î^fp\x90u\x00')
ERROR 2023-04-24 22:04:33,617 You're accessing the development server over HTTPS, but it only supports HTTP.
INFO 2023-04-24 22:04:34,024 code 400, message Bad request version ('**\x13\x01\x13\x02\x13\x03À+À/À,À0Ì©Ì¨À\x13À\x14\x00\x9c\x00\x9d\x00/\x005\x01\x00\x01\x93')
ERROR 2023-04-24 22:04:34,025 You're accessing the development server over HTTPS, but it only supports HTTP.
INFO 2023-04-24 22:05:04,823 code 400, message Bad request version ('\x00\x02\x01\x00\x00')
ERROR 2023-04-24 22:05:04,823 You're accessing the development server over HTTPS, but it only supports HTTP.
INFO 2023-04-24 22:05:05,232 code 400, message Bad request version ('\x02h2\x08http/1.1\x00\x17\x00\x00\x00#\x00\x00\x00')
ERROR 2023-04-24 22:05:05,232 You're accessing the development server over HTTPS, but it only supports HTTP.
INFO 2023-04-24 22:06:07,304 Watching for file changes with StatReloader
INFO 2023-04-24 22:06:10,878 code 400, message Bad request version ('92\x9dûÙ\x88Â')
ERROR 2023-04-24 22:06:10,878 You're accessing the development server over HTTPS, but it only supports HTTP.
INFO 2023-04-24 22:06:11,316 code 400, message Bad request version ('\x9bsÚ9ábJM¶\xadþÙIHÄ\x17¢')
ERROR 2023-04-24 22:06:11,316 You're accessing the development server over HTTPS, but it only supports HTTP.
INFO 2023-04-24 22:07:59,623 code 400, message Bad request version ('\x1a\x1a\x13\x01\x13\x02\x13\x03À+À/À,À0Ì©Ì¨À\x13À\x14\x00\x9c\x00\x9d\x00/\x005\x01\x00\x01\x93')
ERROR 2023-04-24 22:07:59,624 You're accessing the development server over HTTPS, but it only supports HTTP.
INFO 2023-04-24 22:07:59,671 code 400, message Bad request version ('schoobees.comDi\x00\x05\x00\x03\x02h2\x00#\x00\x00\x00+\x00\x07\x06**\x03\x04\x03\x03\x00')
ERROR 2023-04-24 22:07:59,671 You're accessing the development server over HTTPS, but it only supports HTTP.
INFO 2023-04-24 22:08:00,072 code 400, message Bad request version ('õ`\x10\x89Æ³QPÊBv')
ERROR 2023-04-24 22:08:00,072 You're accessing the development server over HTTPS, but it only supports HTTP.
INFO 2023-04-24 22:08:00,239 code 400, message Bad request version ('\x00\x02\x01\x00\x00#\x00\x00\x00')
ERROR 2023-04-24 22:08:00,239 You're accessing the development server over HTTPS, but it only supports HTTP.
INFO 2023-04-27 19:08:58,428 Watching for file changes with StatReloader
ERROR 2023-04-27 21:40:53,028 Internal Server Error: /accounts/register/
Traceback (most recent call last):
  File "/home/ubuntu/schoobeesenv/lib/python3.10/site-packages/django/db/backends/utils.py", line 89, in _execute
    return self.cursor.execute(sql, params)
psycopg2.errors.NumericValueOutOfRange: integer out of range


The above exception was the direct cause of the following exception:

Traceback (most recent call last):
  File "/home/ubuntu/schoobeesenv/lib/python3.10/site-packages/django/core/handlers/exception.py", line 55, in inner
    response = get_response(request)
  File "/home/ubuntu/schoobeesenv/lib/python3.10/site-packages/django/core/handlers/base.py", line 197, in _get_response
    response = wrapped_callback(request, *callback_args, **callback_kwargs)
  File "/home/ubuntu/schoobeesenv/lib/python3.10/site-packages/django/views/generic/base.py", line 104, in view
    return self.dispatch(request, *args, **kwargs)
  File "/home/ubuntu/schoobeesenv/lib/python3.10/site-packages/django/views/generic/base.py", line 143, in dispatch
    return handler(request, *args, **kwargs)
  File "/home/ubuntu/prod-schoobees/apps/base/views.py", line 25, in post
    user.save()
  File "/home/ubuntu/prod-schoobees/apps/base/models.py", line 40, in save
    super().save(*args, **kwargs)
  File "/home/ubuntu/schoobeesenv/lib/python3.10/site-packages/django/contrib/auth/base_user.py", line 76, in save
    super().save(*args, **kwargs)
  File "/home/ubuntu/schoobeesenv/lib/python3.10/site-packages/django/db/models/base.py", line 814, in save
    self.save_base(
  File "/home/ubuntu/schoobeesenv/lib/python3.10/site-packages/django/db/models/base.py", line 877, in save_base
    updated = self._save_table(
  File "/home/ubuntu/schoobeesenv/lib/python3.10/site-packages/django/db/models/base.py", line 1020, in _save_table
    results = self._do_insert(
  File "/home/ubuntu/schoobeesenv/lib/python3.10/site-packages/django/db/models/base.py", line 1061, in _do_insert
    return manager._insert(
  File "/home/ubuntu/schoobeesenv/lib/python3.10/site-packages/django/db/models/manager.py", line 87, in manager_method
    return getattr(self.get_queryset(), name)(*args, **kwargs)
  File "/home/ubuntu/schoobeesenv/lib/python3.10/site-packages/django/db/models/query.py", line 1805, in _insert
    return query.get_compiler(using=using).execute_sql(returning_fields)
  File "/home/ubuntu/schoobeesenv/lib/python3.10/site-packages/django/db/models/sql/compiler.py", line 1820, in execute_sql
    cursor.execute(sql, params)
  File "/home/ubuntu/schoobeesenv/lib/python3.10/site-packages/django/db/backends/utils.py", line 67, in execute
    return self._execute_with_wrappers(
  File "/home/ubuntu/schoobeesenv/lib/python3.10/site-packages/django/db/backends/utils.py", line 80, in _execute_with_wrappers
    return executor(sql, params, many, context)
  File "/home/ubuntu/schoobeesenv/lib/python3.10/site-packages/django/db/backends/utils.py", line 84, in _execute
    with self.db.wrap_database_errors:
  File "/home/ubuntu/schoobeesenv/lib/python3.10/site-packages/django/db/utils.py", line 91, in __exit__
    raise dj_exc_value.with_traceback(traceback) from exc_value
  File "/home/ubuntu/schoobeesenv/lib/python3.10/site-packages/django/db/backends/utils.py", line 89, in _execute
    return self.cursor.execute(sql, params)
django.db.utils.DataError: integer out of range

ERROR 2023-04-27 21:42:44,481 Internal Server Error: /accounts/register/
Traceback (most recent call last):
  File "/home/ubuntu/schoobeesenv/lib/python3.10/site-packages/django/db/backends/utils.py", line 89, in _execute
    return self.cursor.execute(sql, params)
psycopg2.errors.NumericValueOutOfRange: integer out of range


The above exception was the direct cause of the following exception:

Traceback (most recent call last):
  File "/home/ubuntu/schoobeesenv/lib/python3.10/site-packages/django/core/handlers/exception.py", line 55, in inner
    response = get_response(request)
  File "/home/ubuntu/schoobeesenv/lib/python3.10/site-packages/django/core/handlers/base.py", line 197, in _get_response
    response = wrapped_callback(request, *callback_args, **callback_kwargs)
  File "/home/ubuntu/schoobeesenv/lib/python3.10/site-packages/django/views/generic/base.py", line 104, in view
    return self.dispatch(request, *args, **kwargs)
  File "/home/ubuntu/schoobeesenv/lib/python3.10/site-packages/django/views/generic/base.py", line 143, in dispatch
    return handler(request, *args, **kwargs)
  File "/home/ubuntu/prod-schoobees/apps/base/views.py", line 25, in post
    user.save()
  File "/home/ubuntu/prod-schoobees/apps/base/models.py", line 40, in save
    super().save(*args, **kwargs)
  File "/home/ubuntu/schoobeesenv/lib/python3.10/site-packages/django/contrib/auth/base_user.py", line 76, in save
    super().save(*args, **kwargs)
  File "/home/ubuntu/schoobeesenv/lib/python3.10/site-packages/django/db/models/base.py", line 814, in save
    self.save_base(
  File "/home/ubuntu/schoobeesenv/lib/python3.10/site-packages/django/db/models/base.py", line 877, in save_base
    updated = self._save_table(
  File "/home/ubuntu/schoobeesenv/lib/python3.10/site-packages/django/db/models/base.py", line 1020, in _save_table
    results = self._do_insert(
  File "/home/ubuntu/schoobeesenv/lib/python3.10/site-packages/django/db/models/base.py", line 1061, in _do_insert
    return manager._insert(
  File "/home/ubuntu/schoobeesenv/lib/python3.10/site-packages/django/db/models/manager.py", line 87, in manager_method
    return getattr(self.get_queryset(), name)(*args, **kwargs)
  File "/home/ubuntu/schoobeesenv/lib/python3.10/site-packages/django/db/models/query.py", line 1805, in _insert
    return query.get_compiler(using=using).execute_sql(returning_fields)
  File "/home/ubuntu/schoobeesenv/lib/python3.10/site-packages/django/db/models/sql/compiler.py", line 1820, in execute_sql
    cursor.execute(sql, params)
  File "/home/ubuntu/schoobeesenv/lib/python3.10/site-packages/django/db/backends/utils.py", line 67, in execute
    return self._execute_with_wrappers(
  File "/home/ubuntu/schoobeesenv/lib/python3.10/site-packages/django/db/backends/utils.py", line 80, in _execute_with_wrappers
    return executor(sql, params, many, context)
  File "/home/ubuntu/schoobeesenv/lib/python3.10/site-packages/django/db/backends/utils.py", line 84, in _execute
    with self.db.wrap_database_errors:
  File "/home/ubuntu/schoobeesenv/lib/python3.10/site-packages/django/db/utils.py", line 91, in __exit__
    raise dj_exc_value.with_traceback(traceback) from exc_value
  File "/home/ubuntu/schoobeesenv/lib/python3.10/site-packages/django/db/backends/utils.py", line 89, in _execute
    return self.cursor.execute(sql, params)
django.db.utils.DataError: integer out of range

ERROR 2023-04-27 21:44:01,995 Internal Server Error: /accounts/register/
Traceback (most recent call last):
  File "/home/ubuntu/schoobeesenv/lib/python3.10/site-packages/django/db/backends/utils.py", line 89, in _execute
    return self.cursor.execute(sql, params)
psycopg2.errors.NumericValueOutOfRange: integer out of range


The above exception was the direct cause of the following exception:

Traceback (most recent call last):
  File "/home/ubuntu/schoobeesenv/lib/python3.10/site-packages/django/core/handlers/exception.py", line 55, in inner
    response = get_response(request)
  File "/home/ubuntu/schoobeesenv/lib/python3.10/site-packages/django/core/handlers/base.py", line 197, in _get_response
    response = wrapped_callback(request, *callback_args, **callback_kwargs)
  File "/home/ubuntu/schoobeesenv/lib/python3.10/site-packages/django/views/generic/base.py", line 104, in view
    return self.dispatch(request, *args, **kwargs)
  File "/home/ubuntu/schoobeesenv/lib/python3.10/site-packages/django/views/generic/base.py", line 143, in dispatch
    return handler(request, *args, **kwargs)
  File "/home/ubuntu/prod-schoobees/apps/base/views.py", line 25, in post
    user.save()
  File "/home/ubuntu/prod-schoobees/apps/base/models.py", line 40, in save
    super().save(*args, **kwargs)
  File "/home/ubuntu/schoobeesenv/lib/python3.10/site-packages/django/contrib/auth/base_user.py", line 76, in save
    super().save(*args, **kwargs)
  File "/home/ubuntu/schoobeesenv/lib/python3.10/site-packages/django/db/models/base.py", line 814, in save
    self.save_base(
  File "/home/ubuntu/schoobeesenv/lib/python3.10/site-packages/django/db/models/base.py", line 877, in save_base
    updated = self._save_table(
  File "/home/ubuntu/schoobeesenv/lib/python3.10/site-packages/django/db/models/base.py", line 1020, in _save_table
    results = self._do_insert(
  File "/home/ubuntu/schoobeesenv/lib/python3.10/site-packages/django/db/models/base.py", line 1061, in _do_insert
    return manager._insert(
  File "/home/ubuntu/schoobeesenv/lib/python3.10/site-packages/django/db/models/manager.py", line 87, in manager_method
    return getattr(self.get_queryset(), name)(*args, **kwargs)
  File "/home/ubuntu/schoobeesenv/lib/python3.10/site-packages/django/db/models/query.py", line 1805, in _insert
    return query.get_compiler(using=using).execute_sql(returning_fields)
  File "/home/ubuntu/schoobeesenv/lib/python3.10/site-packages/django/db/models/sql/compiler.py", line 1820, in execute_sql
    cursor.execute(sql, params)
  File "/home/ubuntu/schoobeesenv/lib/python3.10/site-packages/django/db/backends/utils.py", line 67, in execute
    return self._execute_with_wrappers(
  File "/home/ubuntu/schoobeesenv/lib/python3.10/site-packages/django/db/backends/utils.py", line 80, in _execute_with_wrappers
    return executor(sql, params, many, context)
  File "/home/ubuntu/schoobeesenv/lib/python3.10/site-packages/django/db/backends/utils.py", line 84, in _execute
    with self.db.wrap_database_errors:
  File "/home/ubuntu/schoobeesenv/lib/python3.10/site-packages/django/db/utils.py", line 91, in __exit__
    raise dj_exc_value.with_traceback(traceback) from exc_value
  File "/home/ubuntu/schoobeesenv/lib/python3.10/site-packages/django/db/backends/utils.py", line 89, in _execute
    return self.cursor.execute(sql, params)
django.db.utils.DataError: integer out of range

ERROR 2023-04-27 21:45:38,082 Internal Server Error: /admin/base/customuser/add/
Traceback (most recent call last):
  File "/home/ubuntu/schoobeesenv/lib/python3.10/site-packages/django/db/backends/utils.py", line 89, in _execute
    return self.cursor.execute(sql, params)
psycopg2.errors.NumericValueOutOfRange: integer out of range


The above exception was the direct cause of the following exception:

Traceback (most recent call last):
  File "/home/ubuntu/schoobeesenv/lib/python3.10/site-packages/django/core/handlers/exception.py", line 55, in inner
    response = get_response(request)
  File "/home/ubuntu/schoobeesenv/lib/python3.10/site-packages/django/core/handlers/base.py", line 197, in _get_response
    response = wrapped_callback(request, *callback_args, **callback_kwargs)
  File "/home/ubuntu/schoobeesenv/lib/python3.10/site-packages/django/contrib/admin/options.py", line 688, in wrapper
    return self.admin_site.admin_view(view)(*args, **kwargs)
  File "/home/ubuntu/schoobeesenv/lib/python3.10/site-packages/django/utils/decorators.py", line 134, in _wrapper_view
    response = view_func(request, *args, **kwargs)
  File "/home/ubuntu/schoobeesenv/lib/python3.10/site-packages/django/views/decorators/cache.py", line 62, in _wrapper_view_func
    response = view_func(request, *args, **kwargs)
  File "/home/ubuntu/schoobeesenv/lib/python3.10/site-packages/django/contrib/admin/sites.py", line 242, in inner
    return view(request, *args, **kwargs)
  File "/home/ubuntu/schoobeesenv/lib/python3.10/site-packages/django/utils/decorators.py", line 46, in _wrapper
    return bound_method(*args, **kwargs)
  File "/home/ubuntu/schoobeesenv/lib/python3.10/site-packages/django/views/decorators/debug.py", line 92, in sensitive_post_parameters_wrapper
    return view(request, *args, **kwargs)
  File "/home/ubuntu/schoobeesenv/lib/python3.10/site-packages/django/utils/decorators.py", line 46, in _wrapper
    return bound_method(*args, **kwargs)
  File "/home/ubuntu/schoobeesenv/lib/python3.10/site-packages/django/utils/decorators.py", line 134, in _wrapper_view
    response = view_func(request, *args, **kwargs)
  File "/home/ubuntu/schoobeesenv/lib/python3.10/site-packages/django/contrib/auth/admin.py", line 119, in add_view
    return self._add_view(request, form_url, extra_context)
  File "/home/ubuntu/schoobeesenv/lib/python3.10/site-packages/django/contrib/auth/admin.py", line 147, in _add_view
    return super().add_view(request, form_url, extra_context)
  File "/home/ubuntu/schoobeesenv/lib/python3.10/site-packages/django/contrib/admin/options.py", line 1886, in add_view
    return self.changeform_view(request, None, form_url, extra_context)
  File "/home/ubuntu/schoobeesenv/lib/python3.10/site-packages/django/utils/decorators.py", line 46, in _wrapper
    return bound_method(*args, **kwargs)
  File "/home/ubuntu/schoobeesenv/lib/python3.10/site-packages/django/utils/decorators.py", line 134, in _wrapper_view
    response = view_func(request, *args, **kwargs)
  File "/home/ubuntu/schoobeesenv/lib/python3.10/site-packages/django/contrib/admin/options.py", line 1747, in changeform_view
    return self._changeform_view(request, object_id, form_url, extra_context)
  File "/home/ubuntu/schoobeesenv/lib/python3.10/site-packages/django/contrib/admin/options.py", line 1798, in _changeform_view
    self.save_model(request, new_object, form, not add)
  File "/home/ubuntu/schoobeesenv/lib/python3.10/site-packages/django/contrib/admin/options.py", line 1227, in save_model
    obj.save()
  File "/home/ubuntu/prod-schoobees/apps/base/models.py", line 40, in save
    super().save(*args, **kwargs)
  File "/home/ubuntu/schoobeesenv/lib/python3.10/site-packages/django/contrib/auth/base_user.py", line 76, in save
    super().save(*args, **kwargs)
  File "/home/ubuntu/schoobeesenv/lib/python3.10/site-packages/django/db/models/base.py", line 814, in save
    self.save_base(
  File "/home/ubuntu/schoobeesenv/lib/python3.10/site-packages/django/db/models/base.py", line 877, in save_base
    updated = self._save_table(
  File "/home/ubuntu/schoobeesenv/lib/python3.10/site-packages/django/db/models/base.py", line 1020, in _save_table
    results = self._do_insert(
  File "/home/ubuntu/schoobeesenv/lib/python3.10/site-packages/django/db/models/base.py", line 1061, in _do_insert
    return manager._insert(
  File "/home/ubuntu/schoobeesenv/lib/python3.10/site-packages/django/db/models/manager.py", line 87, in manager_method
    return getattr(self.get_queryset(), name)(*args, **kwargs)
  File "/home/ubuntu/schoobeesenv/lib/python3.10/site-packages/django/db/models/query.py", line 1805, in _insert
    return query.get_compiler(using=using).execute_sql(returning_fields)
  File "/home/ubuntu/schoobeesenv/lib/python3.10/site-packages/django/db/models/sql/compiler.py", line 1820, in execute_sql
    cursor.execute(sql, params)
  File "/home/ubuntu/schoobeesenv/lib/python3.10/site-packages/django/db/backends/utils.py", line 67, in execute
    return self._execute_with_wrappers(
  File "/home/ubuntu/schoobeesenv/lib/python3.10/site-packages/django/db/backends/utils.py", line 80, in _execute_with_wrappers
    return executor(sql, params, many, context)
  File "/home/ubuntu/schoobeesenv/lib/python3.10/site-packages/django/db/backends/utils.py", line 84, in _execute
    with self.db.wrap_database_errors:
  File "/home/ubuntu/schoobeesenv/lib/python3.10/site-packages/django/db/utils.py", line 91, in __exit__
    raise dj_exc_value.with_traceback(traceback) from exc_value
  File "/home/ubuntu/schoobeesenv/lib/python3.10/site-packages/django/db/backends/utils.py", line 89, in _execute
    return self.cursor.execute(sql, params)
django.db.utils.DataError: integer out of range

ERROR 2023-04-27 21:45:46,327 Internal Server Error: /admin/base/customuser/add/
Traceback (most recent call last):
  File "/home/ubuntu/schoobeesenv/lib/python3.10/site-packages/django/db/backends/utils.py", line 89, in _execute
    return self.cursor.execute(sql, params)
psycopg2.errors.NumericValueOutOfRange: integer out of range


The above exception was the direct cause of the following exception:

Traceback (most recent call last):
  File "/home/ubuntu/schoobeesenv/lib/python3.10/site-packages/django/core/handlers/exception.py", line 55, in inner
    response = get_response(request)
  File "/home/ubuntu/schoobeesenv/lib/python3.10/site-packages/django/core/handlers/base.py", line 197, in _get_response
    response = wrapped_callback(request, *callback_args, **callback_kwargs)
  File "/home/ubuntu/schoobeesenv/lib/python3.10/site-packages/django/contrib/admin/options.py", line 688, in wrapper
    return self.admin_site.admin_view(view)(*args, **kwargs)
  File "/home/ubuntu/schoobeesenv/lib/python3.10/site-packages/django/utils/decorators.py", line 134, in _wrapper_view
    response = view_func(request, *args, **kwargs)
  File "/home/ubuntu/schoobeesenv/lib/python3.10/site-packages/django/views/decorators/cache.py", line 62, in _wrapper_view_func
    response = view_func(request, *args, **kwargs)
  File "/home/ubuntu/schoobeesenv/lib/python3.10/site-packages/django/contrib/admin/sites.py", line 242, in inner
    return view(request, *args, **kwargs)
  File "/home/ubuntu/schoobeesenv/lib/python3.10/site-packages/django/utils/decorators.py", line 46, in _wrapper
    return bound_method(*args, **kwargs)
  File "/home/ubuntu/schoobeesenv/lib/python3.10/site-packages/django/views/decorators/debug.py", line 92, in sensitive_post_parameters_wrapper
    return view(request, *args, **kwargs)
  File "/home/ubuntu/schoobeesenv/lib/python3.10/site-packages/django/utils/decorators.py", line 46, in _wrapper
    return bound_method(*args, **kwargs)
  File "/home/ubuntu/schoobeesenv/lib/python3.10/site-packages/django/utils/decorators.py", line 134, in _wrapper_view
    response = view_func(request, *args, **kwargs)
  File "/home/ubuntu/schoobeesenv/lib/python3.10/site-packages/django/contrib/auth/admin.py", line 119, in add_view
    return self._add_view(request, form_url, extra_context)
  File "/home/ubuntu/schoobeesenv/lib/python3.10/site-packages/django/contrib/auth/admin.py", line 147, in _add_view
    return super().add_view(request, form_url, extra_context)
  File "/home/ubuntu/schoobeesenv/lib/python3.10/site-packages/django/contrib/admin/options.py", line 1886, in add_view
    return self.changeform_view(request, None, form_url, extra_context)
  File "/home/ubuntu/schoobeesenv/lib/python3.10/site-packages/django/utils/decorators.py", line 46, in _wrapper
    return bound_method(*args, **kwargs)
  File "/home/ubuntu/schoobeesenv/lib/python3.10/site-packages/django/utils/decorators.py", line 134, in _wrapper_view
    response = view_func(request, *args, **kwargs)
  File "/home/ubuntu/schoobeesenv/lib/python3.10/site-packages/django/contrib/admin/options.py", line 1747, in changeform_view
    return self._changeform_view(request, object_id, form_url, extra_context)
  File "/home/ubuntu/schoobeesenv/lib/python3.10/site-packages/django/contrib/admin/options.py", line 1798, in _changeform_view
    self.save_model(request, new_object, form, not add)
  File "/home/ubuntu/schoobeesenv/lib/python3.10/site-packages/django/contrib/admin/options.py", line 1227, in save_model
    obj.save()
  File "/home/ubuntu/prod-schoobees/apps/base/models.py", line 40, in save
    super().save(*args, **kwargs)
  File "/home/ubuntu/schoobeesenv/lib/python3.10/site-packages/django/contrib/auth/base_user.py", line 76, in save
    super().save(*args, **kwargs)
  File "/home/ubuntu/schoobeesenv/lib/python3.10/site-packages/django/db/models/base.py", line 814, in save
    self.save_base(
  File "/home/ubuntu/schoobeesenv/lib/python3.10/site-packages/django/db/models/base.py", line 877, in save_base
    updated = self._save_table(
  File "/home/ubuntu/schoobeesenv/lib/python3.10/site-packages/django/db/models/base.py", line 1020, in _save_table
    results = self._do_insert(
  File "/home/ubuntu/schoobeesenv/lib/python3.10/site-packages/django/db/models/base.py", line 1061, in _do_insert
    return manager._insert(
  File "/home/ubuntu/schoobeesenv/lib/python3.10/site-packages/django/db/models/manager.py", line 87, in manager_method
    return getattr(self.get_queryset(), name)(*args, **kwargs)
  File "/home/ubuntu/schoobeesenv/lib/python3.10/site-packages/django/db/models/query.py", line 1805, in _insert
    return query.get_compiler(using=using).execute_sql(returning_fields)
  File "/home/ubuntu/schoobeesenv/lib/python3.10/site-packages/django/db/models/sql/compiler.py", line 1820, in execute_sql
    cursor.execute(sql, params)
  File "/home/ubuntu/schoobeesenv/lib/python3.10/site-packages/django/db/backends/utils.py", line 67, in execute
    return self._execute_with_wrappers(
  File "/home/ubuntu/schoobeesenv/lib/python3.10/site-packages/django/db/backends/utils.py", line 80, in _execute_with_wrappers
    return executor(sql, params, many, context)
  File "/home/ubuntu/schoobeesenv/lib/python3.10/site-packages/django/db/backends/utils.py", line 84, in _execute
    with self.db.wrap_database_errors:
  File "/home/ubuntu/schoobeesenv/lib/python3.10/site-packages/django/db/utils.py", line 91, in __exit__
    raise dj_exc_value.with_traceback(traceback) from exc_value
  File "/home/ubuntu/schoobeesenv/lib/python3.10/site-packages/django/db/backends/utils.py", line 89, in _execute
    return self.cursor.execute(sql, params)
django.db.utils.DataError: integer out of range

ERROR 2023-04-27 21:51:07,966 Internal Server Error: /accounts/register/
Traceback (most recent call last):
  File "/home/ubuntu/schoobeesenv/lib/python3.10/site-packages/django/db/backends/utils.py", line 89, in _execute
    return self.cursor.execute(sql, params)
psycopg2.errors.NumericValueOutOfRange: integer out of range


The above exception was the direct cause of the following exception:

Traceback (most recent call last):
  File "/home/ubuntu/schoobeesenv/lib/python3.10/site-packages/django/core/handlers/exception.py", line 55, in inner
    response = get_response(request)
  File "/home/ubuntu/schoobeesenv/lib/python3.10/site-packages/django/core/handlers/base.py", line 197, in _get_response
    response = wrapped_callback(request, *callback_args, **callback_kwargs)
  File "/home/ubuntu/schoobeesenv/lib/python3.10/site-packages/django/views/generic/base.py", line 104, in view
    return self.dispatch(request, *args, **kwargs)
  File "/home/ubuntu/schoobeesenv/lib/python3.10/site-packages/django/views/generic/base.py", line 143, in dispatch
    return handler(request, *args, **kwargs)
  File "/home/ubuntu/prod-schoobees/apps/base/views.py", line 25, in post
    user.save()
  File "/home/ubuntu/prod-schoobees/apps/base/models.py", line 40, in save
    super().save(*args, **kwargs)
  File "/home/ubuntu/schoobeesenv/lib/python3.10/site-packages/django/contrib/auth/base_user.py", line 76, in save
    super().save(*args, **kwargs)
  File "/home/ubuntu/schoobeesenv/lib/python3.10/site-packages/django/db/models/base.py", line 814, in save
    self.save_base(
  File "/home/ubuntu/schoobeesenv/lib/python3.10/site-packages/django/db/models/base.py", line 877, in save_base
    updated = self._save_table(
  File "/home/ubuntu/schoobeesenv/lib/python3.10/site-packages/django/db/models/base.py", line 1020, in _save_table
    results = self._do_insert(
  File "/home/ubuntu/schoobeesenv/lib/python3.10/site-packages/django/db/models/base.py", line 1061, in _do_insert
    return manager._insert(
  File "/home/ubuntu/schoobeesenv/lib/python3.10/site-packages/django/db/models/manager.py", line 87, in manager_method
    return getattr(self.get_queryset(), name)(*args, **kwargs)
  File "/home/ubuntu/schoobeesenv/lib/python3.10/site-packages/django/db/models/query.py", line 1805, in _insert
    return query.get_compiler(using=using).execute_sql(returning_fields)
  File "/home/ubuntu/schoobeesenv/lib/python3.10/site-packages/django/db/models/sql/compiler.py", line 1820, in execute_sql
    cursor.execute(sql, params)
  File "/home/ubuntu/schoobeesenv/lib/python3.10/site-packages/django/db/backends/utils.py", line 67, in execute
    return self._execute_with_wrappers(
  File "/home/ubuntu/schoobeesenv/lib/python3.10/site-packages/django/db/backends/utils.py", line 80, in _execute_with_wrappers
    return executor(sql, params, many, context)
  File "/home/ubuntu/schoobeesenv/lib/python3.10/site-packages/django/db/backends/utils.py", line 84, in _execute
    with self.db.wrap_database_errors:
  File "/home/ubuntu/schoobeesenv/lib/python3.10/site-packages/django/db/utils.py", line 91, in __exit__
    raise dj_exc_value.with_traceback(traceback) from exc_value
  File "/home/ubuntu/schoobeesenv/lib/python3.10/site-packages/django/db/backends/utils.py", line 89, in _execute
    return self.cursor.execute(sql, params)
django.db.utils.DataError: integer out of range

WARNING 2023-04-28 13:28:05,878 Forbidden (Referer checking failed - no Referer.): /
WARNING 2023-04-28 17:11:47,928 Forbidden (Referer checking failed - no Referer.): /
ERROR 2023-04-28 17:31:18,491 Internal Server Error: /accounts/register/
Traceback (most recent call last):
  File "/home/ubuntu/schoobeesenv/lib/python3.10/site-packages/django/db/backends/utils.py", line 89, in _execute
    return self.cursor.execute(sql, params)
psycopg2.errors.NumericValueOutOfRange: integer out of range


The above exception was the direct cause of the following exception:

Traceback (most recent call last):
  File "/home/ubuntu/schoobeesenv/lib/python3.10/site-packages/django/core/handlers/exception.py", line 55, in inner
    response = get_response(request)
  File "/home/ubuntu/schoobeesenv/lib/python3.10/site-packages/django/core/handlers/base.py", line 197, in _get_response
    response = wrapped_callback(request, *callback_args, **callback_kwargs)
  File "/home/ubuntu/schoobeesenv/lib/python3.10/site-packages/django/views/generic/base.py", line 104, in view
    return self.dispatch(request, *args, **kwargs)
  File "/home/ubuntu/schoobeesenv/lib/python3.10/site-packages/django/views/generic/base.py", line 143, in dispatch
    return handler(request, *args, **kwargs)
  File "/home/ubuntu/prod-schoobees/apps/base/views.py", line 25, in post
    user.save()
  File "/home/ubuntu/prod-schoobees/apps/base/models.py", line 40, in save
    super().save(*args, **kwargs)
  File "/home/ubuntu/schoobeesenv/lib/python3.10/site-packages/django/contrib/auth/base_user.py", line 76, in save
    super().save(*args, **kwargs)
  File "/home/ubuntu/schoobeesenv/lib/python3.10/site-packages/django/db/models/base.py", line 814, in save
    self.save_base(
  File "/home/ubuntu/schoobeesenv/lib/python3.10/site-packages/django/db/models/base.py", line 877, in save_base
    updated = self._save_table(
  File "/home/ubuntu/schoobeesenv/lib/python3.10/site-packages/django/db/models/base.py", line 1020, in _save_table
    results = self._do_insert(
  File "/home/ubuntu/schoobeesenv/lib/python3.10/site-packages/django/db/models/base.py", line 1061, in _do_insert
    return manager._insert(
  File "/home/ubuntu/schoobeesenv/lib/python3.10/site-packages/django/db/models/manager.py", line 87, in manager_method
    return getattr(self.get_queryset(), name)(*args, **kwargs)
  File "/home/ubuntu/schoobeesenv/lib/python3.10/site-packages/django/db/models/query.py", line 1805, in _insert
    return query.get_compiler(using=using).execute_sql(returning_fields)
  File "/home/ubuntu/schoobeesenv/lib/python3.10/site-packages/django/db/models/sql/compiler.py", line 1820, in execute_sql
    cursor.execute(sql, params)
  File "/home/ubuntu/schoobeesenv/lib/python3.10/site-packages/django/db/backends/utils.py", line 67, in execute
    return self._execute_with_wrappers(
  File "/home/ubuntu/schoobeesenv/lib/python3.10/site-packages/django/db/backends/utils.py", line 80, in _execute_with_wrappers
    return executor(sql, params, many, context)
  File "/home/ubuntu/schoobeesenv/lib/python3.10/site-packages/django/db/backends/utils.py", line 84, in _execute
    with self.db.wrap_database_errors:
  File "/home/ubuntu/schoobeesenv/lib/python3.10/site-packages/django/db/utils.py", line 91, in __exit__
    raise dj_exc_value.with_traceback(traceback) from exc_value
  File "/home/ubuntu/schoobeesenv/lib/python3.10/site-packages/django/db/backends/utils.py", line 89, in _execute
    return self.cursor.execute(sql, params)
django.db.utils.DataError: integer out of range

